[35mDEBUG   [0m tests.conftest:conftest.py:43 Running fixture setup: test_id
[35mDEBUG   [0m tests.conftest:conftest.py:49 Running test: test_relay_unsubscribe_with_invalid_pubsub_topic_format with id: 2024-01-18_11-05-57__25dad992-4885-459f-b5c9-3c0d41d54496
[35mDEBUG   [0m src.steps.relay:relay.py:23 Running fixture setup: relay_setup
[35mDEBUG   [0m src.steps.relay:relay.py:29 Running fixture setup: setup_main_relay_nodes
[35mDEBUG   [0m src.node.docker_mananger:docker_mananger.py:17 Docker client initialized with image harbor.status.im/wakuorg/go-waku:latest
[35mDEBUG   [0m src.node.waku_node:waku_node.py:21 WakuNode instance initialized with log path ./log/docker/node1_2024-01-18_11-05-57__25dad992-4885-459f-b5c9-3c0d41d54496__harbor.status.im_wakuorg_go-waku:latest.log
[35mDEBUG   [0m src.node.waku_node:waku_node.py:25 Starting Node...
[35mDEBUG   [0m src.node.docker_mananger:docker_mananger.py:20 Attempting to create or retrieve network waku
[35mDEBUG   [0m src.node.docker_mananger:docker_mananger.py:23 Network waku already exists
[35mDEBUG   [0m src.node.docker_mananger:docker_mananger.py:73 Generated random external IP 172.18.156.153
[35mDEBUG   [0m src.node.docker_mananger:docker_mananger.py:66 Generated ports ['46868', '46869', '46870', '46871', '46872']
[35mDEBUG   [0m src.node.docker_mananger:docker_mananger.py:42 Starting container with image harbor.status.im/wakuorg/go-waku:latest
[35mDEBUG   [0m src.node.docker_mananger:docker_mananger.py:43 Using args ['--listen-address=0.0.0.0', '--rest=true', '--rest-admin=true', '--websocket-support=true', '--log-level=DEBUG', '--rest-relay-cache-capacity=100', '--websocket-port=46870', '--rest-port=46868', '--tcp-port=46869', '--discv5-udp-port=46871', '--rest-address=0.0.0.0', '--nat=extip:172.18.156.153', '--peer-exchange=true', '--discv5-discovery=true', '--cluster-id=0', '--min-relay-peers-to-publish=1', '--legacy-filter=false', '--rest-filter-cache-capacity=50', '--relay=true', '--nodekey=30348dd51465150e04a5d9d932c72864c8967f806cce60b5d26afeca1e77eb68']
[35mDEBUG   [0m src.node.docker_mananger:docker_mananger.py:49 Container started with ID dfb4e5cd8713. Setting up logs at ./log/docker/node1_2024-01-18_11-05-57__25dad992-4885-459f-b5c9-3c0d41d54496__harbor.status.im_wakuorg_go-waku:latest.log
[35mDEBUG   [0m src.node.waku_node:waku_node.py:78 Started container from image harbor.status.im/wakuorg/go-waku:latest. REST: 46868
[35mDEBUG   [0m src.libs.common:common.py:33 Sleeping for 1 seconds
[32mINFO    [0m src.node.api_clients.base_client:base_client.py:11 GET call: http://127.0.0.1:46868/debug/v1/info with payload: None
[32mINFO    [0m src.node.api_clients.base_client:base_client.py:22 Response status code: 200. Response content: b'{"enrUri":"enr:-Ly4QFVIs2dIshRDplhmOTT4hXLDTX5Wjy6wf586xTdmJSIUNQDMDx3HpQT0GpouPwdesuZQwDKFqWdcoyodlPDyoD2GAY0cP8ecgmlkgnY0gmlwhKwRAAKKbXVsdGlhZGRyc5gACgSsEQACBrcW3QMACgR_AAABBrcW3QOJc2VjcDI1NmsxoQM3Tqpf5eFn4Jztm4gB0Y0JVSJyxyZsW8QR-QU5DZb-PYN0Y3CCtxWDdWRwgrcXhXdha3UyAQ","listenAddresses":["/ip4/127.0.0.1/tcp/46869/p2p/16Uiu2HAmGNtM2rQ8abySFNhqPDFY4cmfAEpfo9Z9fD3NekoFR2ip","/ip4/127.0.0.1/tcp/46870/ws/p2p/16Uiu2HAmGNtM2rQ8abySFNhqPDFY4cmfAEpfo9Z9fD3NekoFR2ip","/ip4/172.17.0.2/tcp/46869/p2p/16Uiu2HAmGNtM2rQ8abySFNhqPDFY4cmfAEpfo9Z9fD3NekoFR2ip","/ip4/172.17.0.2/tcp/46870/ws/p2p/16Uiu2HAmGNtM2rQ8abySFNhqPDFY4cmfAEpfo9Z9fD3NekoFR2ip"]}'
[32mINFO    [0m src.node.waku_node:waku_node.py:113 REST service is ready !!
[35mDEBUG   [0m src.node.docker_mananger:docker_mananger.py:17 Docker client initialized with image harbor.status.im/wakuorg/go-waku:latest
[35mDEBUG   [0m src.node.waku_node:waku_node.py:21 WakuNode instance initialized with log path ./log/docker/node2_2024-01-18_11-05-57__25dad992-4885-459f-b5c9-3c0d41d54496__harbor.status.im_wakuorg_go-waku:latest.log
[35mDEBUG   [0m src.node.waku_node:waku_node.py:25 Starting Node...
[35mDEBUG   [0m src.node.docker_mananger:docker_mananger.py:20 Attempting to create or retrieve network waku
[35mDEBUG   [0m src.node.docker_mananger:docker_mananger.py:23 Network waku already exists
[35mDEBUG   [0m src.node.docker_mananger:docker_mananger.py:73 Generated random external IP 172.18.110.111
[35mDEBUG   [0m src.node.docker_mananger:docker_mananger.py:66 Generated ports ['12180', '12181', '12182', '12183', '12184']
[35mDEBUG   [0m src.node.docker_mananger:docker_mananger.py:42 Starting container with image harbor.status.im/wakuorg/go-waku:latest
[35mDEBUG   [0m src.node.docker_mananger:docker_mananger.py:43 Using args ['--listen-address=0.0.0.0', '--rest=true', '--rest-admin=true', '--websocket-support=true', '--log-level=DEBUG', '--rest-relay-cache-capacity=100', '--websocket-port=12182', '--rest-port=12180', '--tcp-port=12181', '--discv5-udp-port=12183', '--rest-address=0.0.0.0', '--nat=extip:172.18.110.111', '--peer-exchange=true', '--discv5-discovery=true', '--cluster-id=0', '--min-relay-peers-to-publish=1', '--legacy-filter=false', '--rest-filter-cache-capacity=50', '--relay=true', '--discv5-bootstrap-node=enr:-Ly4QFVIs2dIshRDplhmOTT4hXLDTX5Wjy6wf586xTdmJSIUNQDMDx3HpQT0GpouPwdesuZQwDKFqWdcoyodlPDyoD2GAY0cP8ecgmlkgnY0gmlwhKwRAAKKbXVsdGlhZGRyc5gACgSsEQACBrcW3QMACgR_AAABBrcW3QOJc2VjcDI1NmsxoQM3Tqpf5eFn4Jztm4gB0Y0JVSJyxyZsW8QR-QU5DZb-PYN0Y3CCtxWDdWRwgrcXhXdha3UyAQ']
[35mDEBUG   [0m src.node.docker_mananger:docker_mananger.py:49 Container started with ID 045da40d2d0f. Setting up logs at ./log/docker/node2_2024-01-18_11-05-57__25dad992-4885-459f-b5c9-3c0d41d54496__harbor.status.im_wakuorg_go-waku:latest.log
[35mDEBUG   [0m src.node.waku_node:waku_node.py:78 Started container from image harbor.status.im/wakuorg/go-waku:latest. REST: 12180
[35mDEBUG   [0m src.libs.common:common.py:33 Sleeping for 1 seconds
[32mINFO    [0m src.node.api_clients.base_client:base_client.py:11 GET call: http://127.0.0.1:12180/debug/v1/info with payload: None
[32mINFO    [0m src.node.api_clients.base_client:base_client.py:22 Response status code: 200. Response content: b'{"enrUri":"enr:-Ly4QGv63t9ARPsj9N0dtRy1DJy58QkQRBx-Tc-_FyoFoQqjMzMy3eSo0k1OzJMjxjHBRBQNaWQZy8TGDkaOZ6PNT3CGAY0cP88HgmlkgnY0gmlwhKwRAASKbXVsdGlhZGRyc5gACgR_AAABBi-W3QMACgSsEQAEBi-W3QOJc2VjcDI1NmsxoQNCNzDFihx8FyvvdZRQNYP7khDfvPBnsV4VTwxGL0dGaYN0Y3CCL5WDdWRwgi-XhXdha3UyAQ","listenAddresses":["/ip4/127.0.0.1/tcp/12181/p2p/16Uiu2HAmH7U4ytMHSWRwwdgBwr8pxMqpjFaBP2cKaudXScYAbd4k","/ip4/127.0.0.1/tcp/12182/ws/p2p/16Uiu2HAmH7U4ytMHSWRwwdgBwr8pxMqpjFaBP2cKaudXScYAbd4k","/ip4/172.17.0.4/tcp/12181/p2p/16Uiu2HAmH7U4ytMHSWRwwdgBwr8pxMqpjFaBP2cKaudXScYAbd4k","/ip4/172.17.0.4/tcp/12182/ws/p2p/16Uiu2HAmH7U4ytMHSWRwwdgBwr8pxMqpjFaBP2cKaudXScYAbd4k"]}'
[32mINFO    [0m src.node.waku_node:waku_node.py:113 REST service is ready !!
[35mDEBUG   [0m tests.relay.test_subscribe:test_subscribe.py:87 Running test with payload /test/2/rs/0/1
[32mINFO    [0m src.node.api_clients.base_client:base_client.py:11 DELETE call: http://127.0.0.1:46868/relay/v1/subscriptions with payload: "/test/2/rs/0/1"
[31m[1mERROR   [0m src.node.api_clients.base_client:base_client.py:16 HTTP error occurred: 400 Client Error: Bad Request for url: http://127.0.0.1:46868/relay/v1/subscriptions. Response content: b''
[35mDEBUG   [0m tests.relay.test_subscribe:test_subscribe.py:87 Running test with payload /waku/3/rs/0/1
[32mINFO    [0m src.node.api_clients.base_client:base_client.py:11 DELETE call: http://127.0.0.1:46868/relay/v1/subscriptions with payload: "/waku/3/rs/0/1"
[31m[1mERROR   [0m src.node.api_clients.base_client:base_client.py:16 HTTP error occurred: 400 Client Error: Bad Request for url: http://127.0.0.1:46868/relay/v1/subscriptions. Response content: b''
[35mDEBUG   [0m tests.relay.test_subscribe:test_subscribe.py:87 Running test with payload /waku/2/test/0/1
[32mINFO    [0m src.node.api_clients.base_client:base_client.py:11 DELETE call: http://127.0.0.1:46868/relay/v1/subscriptions with payload: "/waku/2/test/0/1"
[31m[1mERROR   [0m src.node.api_clients.base_client:base_client.py:16 HTTP error occurred: 400 Client Error: Bad Request for url: http://127.0.0.1:46868/relay/v1/subscriptions. Response content: b''
[35mDEBUG   [0m tests.relay.test_subscribe:test_subscribe.py:87 Running test with payload /waku/2/rs/0/b
[32mINFO    [0m src.node.api_clients.base_client:base_client.py:11 DELETE call: http://127.0.0.1:46868/relay/v1/subscriptions with payload: "/waku/2/rs/0/b"
[31m[1mERROR   [0m src.node.api_clients.base_client:base_client.py:16 HTTP error occurred: 400 Client Error: Bad Request for url: http://127.0.0.1:46868/relay/v1/subscriptions. Response content: b''
[35mDEBUG   [0m tests.relay.test_subscribe:test_subscribe.py:87 Running test with payload /waku/2/rs/0
[32mINFO    [0m src.node.api_clients.base_client:base_client.py:11 DELETE call: http://127.0.0.1:46868/relay/v1/subscriptions with payload: "/waku/2/rs/0"
[31m[1mERROR   [0m src.node.api_clients.base_client:base_client.py:16 HTTP error occurred: 400 Client Error: Bad Request for url: http://127.0.0.1:46868/relay/v1/subscriptions. Response content: b''
[35mDEBUG   [0m tests.conftest:conftest.py:51 Running fixture teardown: test_setup
[35mDEBUG   [0m tests.conftest:conftest.py:75 Running fixture teardown: close_open_nodes
[35mDEBUG   [0m src.node.waku_node:waku_node.py:90 Stopping container with id dfb4e5cd8713
[35mDEBUG   [0m src.node.waku_node:waku_node.py:93 Container stopped.
[35mDEBUG   [0m src.node.waku_node:waku_node.py:90 Stopping container with id 045da40d2d0f
[35mDEBUG   [0m src.node.waku_node:waku_node.py:93 Container stopped.
[35mDEBUG   [0m tests.conftest:conftest.py:32 Running fixture teardown: set_allure_env_variables